[2024-04-08T01:51:49.201+0530] {taskinstance.py:1956} INFO - Dependencies all met for dep_context=non-requeueable deps ti=<TaskInstance: analytics_pipeline.check_archive manual__2024-04-07T20:15:32.965247+00:00 [queued]>
[2024-04-08T01:51:49.209+0530] {taskinstance.py:1956} INFO - Dependencies all met for dep_context=requeueable deps ti=<TaskInstance: analytics_pipeline.check_archive manual__2024-04-07T20:15:32.965247+00:00 [queued]>
[2024-04-08T01:51:49.210+0530] {taskinstance.py:2170} INFO - Starting attempt 2 of 2
[2024-04-08T01:51:49.226+0530] {taskinstance.py:2191} INFO - Executing <Task(BranchPythonOperator): check_archive> on 2024-04-07 20:15:32.965247+00:00
[2024-04-08T01:51:49.232+0530] {standard_task_runner.py:60} INFO - Started process 85042 to run task
[2024-04-08T01:51:49.235+0530] {standard_task_runner.py:87} INFO - Running: ['airflow', 'tasks', 'run', 'analytics_pipeline', 'check_archive', 'manual__2024-04-07T20:15:32.965247+00:00', '--job-id', '315', '--raw', '--subdir', 'DAGS_FOLDER/analytics_pipeline.py', '--cfg-path', '/tmp/tmp56emm4m0']
[2024-04-08T01:51:49.235+0530] {standard_task_runner.py:88} INFO - Job 315: Subtask check_archive
[2024-04-08T01:51:49.273+0530] {task_command.py:423} INFO - Running <TaskInstance: analytics_pipeline.check_archive manual__2024-04-07T20:15:32.965247+00:00 [running]> on host LAPTOP-HO799B2R.
[2024-04-08T01:51:49.332+0530] {taskinstance.py:2480} INFO - Exporting env vars: AIRFLOW_CTX_DAG_OWNER='airflow' AIRFLOW_CTX_DAG_ID='analytics_pipeline' AIRFLOW_CTX_TASK_ID='check_archive' AIRFLOW_CTX_EXECUTION_DATE='2024-04-07T20:15:32.965247+00:00' AIRFLOW_CTX_TRY_NUMBER='2' AIRFLOW_CTX_DAG_RUN_ID='manual__2024-04-07T20:15:32.965247+00:00'
[2024-04-08T01:51:49.333+0530] {python.py:201} INFO - Done. Returned value was: valid_archive
[2024-04-08T01:51:49.334+0530] {branch.py:35} INFO - Branch into valid_archive
[2024-04-08T01:51:49.334+0530] {skipmixin.py:178} INFO - Following branch valid_archive
[2024-04-08T01:51:49.339+0530] {taskinstance.py:2698} ERROR - Task failed with exception
Traceback (most recent call last):
  File "/home/lucky/.local/lib/python3.10/site-packages/airflow/models/taskinstance.py", line 433, in _execute_task
    result = execute_callable(context=context, **execute_callable_kwargs)
  File "/home/lucky/.local/lib/python3.10/site-packages/airflow/operators/python.py", line 233, in execute
    return self.do_branch(context, super().execute(context))
  File "/home/lucky/.local/lib/python3.10/site-packages/airflow/operators/branch.py", line 36, in do_branch
    self.skip_all_except(context["ti"], branches_to_execute)
  File "/home/lucky/.local/lib/python3.10/site-packages/airflow/models/skipmixin.py", line 213, in skip_all_except
    raise AirflowException(
airflow.exceptions.AirflowException: 'branch_task_ids' must contain only valid task_ids. Invalid tasks found: {'valid_archive'}.
[2024-04-08T01:51:49.342+0530] {taskinstance.py:1138} INFO - Marking task as FAILED. dag_id=analytics_pipeline, task_id=check_archive, execution_date=20240407T201532, start_date=20240407T202149, end_date=20240407T202149
[2024-04-08T01:51:49.355+0530] {standard_task_runner.py:107} ERROR - Failed to execute job 315 for task check_archive ('branch_task_ids' must contain only valid task_ids. Invalid tasks found: {'valid_archive'}.; 85042)
[2024-04-08T01:51:49.368+0530] {local_task_job_runner.py:234} INFO - Task exited with return code 1
[2024-04-08T01:51:49.392+0530] {taskinstance.py:3280} INFO - 0 downstream tasks scheduled from follow-on schedule check
